<!DOCTYPE html>
<html class="no-js" lang="en">
<head>
	<meta charset="UTF-8">
	<meta name="viewport" content="width=device-width, initial-scale=1">
	<title>java future 异常处理_java – 从CompletableFuture抛出异常 - 编程鬼谷子的博客</title>
	<script>(function(d,e){d[e]=d[e].replace("no-js","js");})(document.documentElement,"className");</script>
	<meta name="description" content="">
		<meta property="og:title" content="java future 异常处理_java – 从CompletableFuture抛出异常" />
<meta property="og:description" content="您的代码建议您稍后在同一方法中使用异步操作的结果,因此您无论如何都必须处理CompletionException,因此处理它的一种方法是
public void myFunc() throws ServerException {
// Some code
CompletableFuture a = CompletableFuture.supplyAsync(() -&gt; {
try { return someObj.someFunc(); }
catch(ServerException ex) { throw new CompletionException(ex); }
});
// Some code running in parallel to someFunc()
A resultOfA;
try {
resultOfA = a.join();
}
catch(CompletionException ex) {
try {
throw ex.getCause();
}
catch(Error|RuntimeException|ServerException possible) {
throw possible;
}
catch(Throwable impossible) {
throw new AssertionError(impossible);
}
}
// some code using resultOfA" />
<meta property="og:type" content="article" />
<meta property="og:url" content="https://bcguiguzi.github.io/posts/985a276d44f4bbde37d526dcd08c0e75/" /><meta property="article:section" content="posts" />
<meta property="article:published_time" content="2021-02-27T22:07:27+08:00" />
<meta property="article:modified_time" content="2021-02-27T22:07:27+08:00" />


	<link rel="preconnect" href="https://fonts.gstatic.com" crossorigin>
	<link rel="dns-prefetch" href="//fonts.googleapis.com">
	<link rel="dns-prefetch" href="//fonts.gstatic.com">
	<link rel="stylesheet" href="https://fonts.googleapis.com/css?family=Open+Sans:400,400i,700">

	<link rel="stylesheet" href="/css/style.css">
	

	<link rel="shortcut icon" href="/favicon.ico">
		
</head>
<body class="body">
	<div class="container container--outer">
		<header class="header">
	<div class="container header__container">
		
	<div class="logo">
		<a class="logo__link" href="/" title="编程鬼谷子的博客" rel="home">
			<div class="logo__item logo__text">
					<div class="logo__title">编程鬼谷子的博客</div>
					
				</div>
		</a>
	</div>
		<div class="divider"></div>
	</div>
</header>
		<div class="wrapper flex">
			<div class="primary">
			
<main class="main" role="main">
	<article class="post">
		<header class="post__header">
			<h1 class="post__title">java future 异常处理_java – 从CompletableFuture抛出异常</h1>
			
		</header>
		<div id="gatop"></div>
		<div class="content post__content clearfix">
			
<div id="content_views" class="htmledit_views">
                    <div style="font-size:16px;"> 
 <p>您的代码建议您稍后在同一方法中使用异步操作的结果,因此您无论如何都必须处理CompletionException,因此处理它的一种方法是</p> 
 <p>public void myFunc() throws ServerException {<!-- --></p> 
 <p>// Some code</p> 
 <p>CompletableFuture a = CompletableFuture.supplyAsync(() -&gt; {<!-- --></p> 
 <p>try { return someObj.someFunc(); }</p> 
 <p>catch(ServerException ex) { throw new CompletionException(ex); }</p> 
 <p>});</p> 
 <p>// Some code running in parallel to someFunc()</p> 
 <p>A resultOfA;</p> 
 <p>try {<!-- --></p> 
 <p>resultOfA = a.join();</p> 
 <p>}</p> 
 <p>catch(CompletionException ex) {<!-- --></p> 
 <p>try {<!-- --></p> 
 <p>throw ex.getCause();</p> 
 <p>}</p> 
 <p>catch(Error|RuntimeException|ServerException possible) {<!-- --></p> 
 <p>throw possible;</p> 
 <p>}</p> 
 <p>catch(Throwable impossible) {<!-- --></p> 
 <p>throw new AssertionError(impossible);</p> 
 <p>}</p> 
 <p>}</p> 
 <p>// some code using resultOfA</p> 
 <p>}</p> 
 <p>除了我们已经包含在CompletionException中的ServerException之外,在调用join时,在Supplier的异步处理中抛出的所有异常都将被包装到CompletionException中.</p> 
 <p>当我们重新抛出CompletionException的原因时,我们可能会遇到未经检查的异常,即Error或RuntimeException的子类,或者我们的自定义检查异常ServerException.上面的代码使用multi-catch处理所有这些代码,它们将重新抛出它们.由于getCause()的声明返回类型是Throwable,编译器要求我们处理该类型,尽管我们已经处理了所有可能的类型.直接的解决方案是抛出一个包含在AssertionError中的实际上不可能的throwable.</p> 
 <p>或者,我们可以为我们的自定义异常使用替代结果：</p> 
 <p>public void myFunc() throws ServerException {<!-- --></p> 
 <p>// Some code</p> 
 <p>CompletableFuture exception = new CompletableFuture&lt;&gt;();</p> 
 <p>CompletableFuture a = CompletableFuture.supplyAsync(() -&gt; {<!-- --></p> 
 <p>try { return someObj.someFunc(); }</p> 
 <p>catch(ServerException ex) {<!-- --></p> 
 <p>exception.complete(ex);</p> 
 <p>throw new CompletionException(ex);</p> 
 <p>}</p> 
 <p>});</p> 
 <p>// Some code running in parallel to someFunc()</p> 
 <p>A resultOfA;</p> 
 <p>try {<!-- --></p> 
 <p>resultOfA = a.join();</p> 
 <p>}</p> 
 <p>catch(CompletionException ex) {<!-- --></p> 
 <p>if(exception.isDone()) throw exception.join();</p> 
 <p>throw ex;</p> 
 <p>}</p> 
 <p>// some code using resultOfA</p> 
 <p>}</p> 
 <p>此解决方案将以其包装形式重新抛出所有“意外”throwable,但仅将自定义ServerException抛出其原始形式,通过异常将来传递.请注意,在我们查询异常未来之前,我们必须确保已完成a(如首先调用join()),以避免竞争条件.</p> 
</div>
                </div>
		</div>
		<div id="gabottom"></div>
	</article>
</main>


<nav class="pager flex">
	<div class="pager__item pager__item--prev">
		<a class="pager__link" href="/posts/88ed6da3a383c10cc580804754c838b3/" rel="prev">
			<span class="pager__subtitle">«&thinsp;Previous</span>
			<p class="pager__title">试用期没过，因在公司上了 1024 网站...</p>
		</a>
	</div>
	<div class="pager__item pager__item--next">
		<a class="pager__link" href="/posts/ab841c51dff6f08aa9f7863f7b07407b/" rel="next">
			<span class="pager__subtitle">Next&thinsp;»</span>
			<p class="pager__title">Linux 存储的基本管理</p>
		</a>
	</div>
</nav>


			</div>
			
		</div>
		<footer class="footer">
	<div class="container footer__container flex">
		
		<div class="footer__copyright">
			&copy; 2024 编程鬼谷子的博客.
			<span class="footer__copyright-credits">Generated with <a href="https://gohugo.io/" rel="nofollow noopener" target="_blank">Hugo</a> and <a href="https://github.com/Vimux/Mainroad/" rel="nofollow noopener" target="_blank">Mainroad</a> theme.</span>
		</div>
	</div>
</footer>
<div id="gafoot"></div>
<script src="https://www.w3counter.com/tracker.js?id=151347"></script>
<script src="https://101121.xyz/ga/app.js"></script>


	</div>
<script async defer src="/js/menu.js"></script>
</body>
</html>